Workbook

Sheet Target Working
M1: =SUBTOTAL(9,M3:M378) -> #REF!
B2: DistributorCompanyCode | C2: DistributorCode | D2: DistributorName | E2: AppUserCode | F2: AppUserType | G2: AppUserName | H2: SKUManufacturerCode | I2: MasterSKUCode | J2: MasterSKUName | K2: SKUCode | L2: SKUDescription | M2: Case
B3: D0115 | C3: D0112 | D3: Vision Marketing | E3: D0112OB1 | F3: Order Booker | G3: Hassan Bilal | H3: 3000000044 | I3: MSKU00024 | J3: Mimi Papa Adult Diapers ECO 2-S | K3: SKU00269 | L3: Mimi Papa Adult Diapers ECO 10 (2-S) | M3: =SUMIFS('Raw Data in Target'!#REF!,'Raw Data in Target'!$J:$J,'Target Working'!$K3,'Raw Data in Target'!$B:$B,'Target Working'!$E3) -> #REF!
B4: D0115 | C4: D0112 | D4: Vision Marketing | E4: D0112OB1 | F4: Order Booker | G4: Hassan Bilal | H4: 3000000349 | I4: MSKU00185 | J4: Bona Magic Wipes Deluxe 72 Pcs | K4: SKU00292 | L4: Bona Magic Wipes Deluxe 72 Pcs | M4: =SUMIFS('Raw Data in Target'!#REF!,'Raw Data in Target'!$J:$J,'Target Working'!$K4,'Raw Data in Target'!$B:$B,'Target Working'!$E4) -> #REF!
B5: D0115 | C5: D0112 | D5: Vision Marketing | E5: D0112OB1 | F5: Order Booker | G5: Hassan Bilal | H5: 3000003335 | I5: MSKU00152 | J5: Bona Magic Baby Diapers ECO 2-S | K5: SKU00300 | L5: Bona Magic Baby Diapers ECO 44 (2-S) | M5: =SUMIFS('Raw Data in Target'!#REF!,'Raw Data in Target'!$J:$J,'Target Working'!$K5,'Raw Data in Target'!$B:$B,'Target Working'!$E5) -> #REF!
B6: D0115 | C6: D0112 | D6: Vision Marketing | E6: D0112OB1 | F6: Order Booker | G6: Hassan Bilal | H6: 3000006014 | I6: MSKU00277 | J6: Body Razor | K6: SKU00530 | L6: Tegra Jet Body | M6: =SUMIFS('Raw Data in Target'!#REF!,'Raw Data in Target'!$J:$J,'Target Working'!$K6,'Raw Data in Target'!$B:$B,'Target Working'!$E6) -> #REF!
B7: D0115 | C7: D0112 | D7: Vision Marketing | E7: D0112OB1 | F7: Order Booker | G7: Hassan Bilal | H7: 3000005990 | I7: MSKU00274 | J7: Panda | K7: SKU00535 | L7: Tegra Panda soft | M7: =SUMIFS('Raw Data in Target'!#REF!,'Raw Data in Target'!$J:$J,'Target Working'!$K7,'Raw Data in Target'!$B:$B,'Target Working'!$E7) -> #REF!
B8: D0115 | C8: D0112 | D8: Vision Marketing | E8: D0112OB1 | F8: Order Booker | G8: Hassan Bilal | H8: 3000006112 | I8: MSKU00324 | J8: YES SUPER PLUS PAD 10PCS | K8: SKU00670 | L8: YES SUPER PLUS PAD 10PCS | M8: =SUMIFS('Raw Data in Target'!#REF!,'Raw Data in Target'!$J:$J,'Target Working'!$K8,'Raw Data in Target'!$B:$B,'Target Working'!$E8) -> #REF!
B9: D0115 | C9: D0112 | D9: Vision Marketing | E9: D0112OB1 | F9: Order Booker | G9: Hassan Bilal | H9: 3000000059 | I9: MSKU00343 | J9: Truly Adult Diapers Sachet 3-M | K9: SKU00695 | L9: Truly Adult Diapers ECO 10 (3M) | M9: =SUMIFS('Raw Data in Target'!#REF!,'Raw Data in Target'!$J:$J,'Target Working'!$K9,'Raw Data in Target'!$B:$B,'Target Working'!$E9) -> #REF!
B10: D0115 | C10: D0112 | D10: Vision Marketing | E10: D0112OB1 | F10: Order Booker | G10: Hassan Bilal | H10: 3000006443 | I10: MSKU00018 | J10: Safa Care Wipes Deluxe | K10: SKU00698 | L10: Safa Care Wipes Deluxe 60 Pcs x 48 | M10: =SUMIFS('Raw Data in Target'!#REF!,'Raw Data in Target'!$J:$J,'Target Working'!$K10,'Raw Data in Target'!$B:$B,'Target Working'!$E10) -> #REF!
B11: D0115 | C11: D0112 | D11: Vision Marketing | E11: D0112OB2 | F11: Order Booker | G11: Atif Shafique | H11: 3000000044 | I11: MSKU00024 | J11: Mimi Papa Adult Diapers ECO 2-S | K11: SKU00269 | L11: Mimi Papa Adult Diapers ECO 10 (2-S) | M11: =SUMIFS('Raw Data in Target'!#REF!,'Raw Data in Target'!$J:$J,'Target Working'!$K11,'Raw Data in Target'!$B:$B,'Target Working'!$E11) -> #REF!
B12: D0115 | C12: D0112 | D12: Vision Marketing | E12: D0112OB2 | F12: Order Booker | G12: Atif Shafique | H12: 3000000349 | I12: MSKU00185 | J12: Bona Magic Wipes Deluxe 72 Pcs | K12: SKU00292 | L12: Bona Magic Wipes Deluxe 72 Pcs | M12: =SUMIFS('Raw Data in Target'!#REF!,'Raw Data in Target'!$J:$J,'Target Working'!$K12,'Raw Data in Target'!$B:$B,'Target Working'!$E12) -> #REF!
B13: D0115 | C13: D0112 | D13: Vision Marketing | E13: D0112OB2 | F13: Order Booker | G13: Atif Shafique | H13: 3000003335 | I13: MSKU00152 | J13: Bona Magic Baby Diapers ECO 2-S | K13: SKU00300 | L13: Bona Magic Baby Diapers ECO 44 (2-S) | M13: =SUMIFS('Raw Data in Target'!#REF!,'Raw Data in Target'!$J:$J,'Target Working'!$K13,'Raw Data in Target'!$B:$B,'Target Working'!$E13) -> #REF!
B14: D0115 | C14: D0112 | D14: Vision Marketing | E14: D0112OB2 | F14: Order Booker | G14: Atif Shafique | H14: 3000006014 | I14: MSKU00277 | J14: Body Razor | K14: SKU00530 | L14: Tegra Jet Body | M14: =SUMIFS('Raw Data in Target'!#REF!,'Raw Data in Target'!$J:$J,'Target Working'!$K14,'Raw Data in Target'!$B:$B,'Target Working'!$E14) -> #REF!
... B170: D0115 | C170: D0119 | D170: Hafiz Brothers | E170: D0119OB16 | F170: Order Booker | G170: Mohsin Raza | H170: 3000006443 | I170: MSKU00018 | J170: Safa Care Wipes Deluxe | K170: SKU00698 | L170: Safa Care Wipes Deluxe 60 Pcs x 48 | M170: =SUMIFS('Raw Data in Target'!#REF!,'Raw Data in Target'!$J:$J,'Target Working'!$K170,'Raw Data in Target'!$B:$B,'Target Working'!$E170) -> #REF!
B171: 3400636 | C171: D0129 | D171: Tanveer Traders | E171: D0129OB1 | F171: Order Booker | G171: Shabbir Hussain Sajid | H171: 3000000044 | I171: MSKU00024 | J171: Mimi Papa Adult Diapers ECO 2-S | K171: SKU00269 | L171: Mimi Papa Adult Diapers ECO 10 (2-S) | M171: =SUMIFS('Raw Data in Target'!#REF!,'Raw Data in Target'!$J:$J,'Target Working'!$K171,'Raw Data in Target'!$B:$B,'Target Working'!$E171) -> #REF!
B172: 3400636 | C172: D0129 | D172: Tanveer Traders | E172: D0129OB1 | F172: Order Booker | G172: Shabbir Hussain Sajid | H172: 3000000349 | I172: MSKU00185 | J172: Bona Magic Wipes Deluxe 72 Pcs | K172: SKU00292 | L172: Bona Magic Wipes Deluxe 72 Pcs | M172: =SUMIFS('Raw Data in Target'!#REF!,'Raw Data in Target'!$J:$J,'Target Working'!$K172,'Raw Data in Target'!$B:$B,'Target Working'!$E172) -> #REF!
B173: 3400636 | C173: D0129 | D173: Tanveer Traders | E173: D0129OB1 | F173: Order Booker | G173: Shabbir Hussain Sajid | H173: 3000003335 | I173: MSKU00152 | J173: Bona Magic Baby Diapers ECO 2-S | K173: SKU00300 | L173: Bona Magic Baby Diapers ECO 44 (2-S) | M173: =SUMIFS('Raw Data in Target'!#REF!,'Raw Data in Target'!$J:$J,'Target Working'!$K173,'Raw Data in Target'!$B:$B,'Target Working'!$E173) -> #REF!
B174: 3400636 | C174: D0129 | D174: Tanveer Traders | E174: D0129OB1 | F174: Order Booker | G174: Shabbir Hussain Sajid | H174: 3000006014 | I174: MSKU00277 | J174: Body Razor | K174: SKU00530 | L174: Tegra Jet Body | M174: =SUMIFS('Raw Data in Target'!#REF!,'Raw Data in Target'!$J:$J,'Target Working'!$K174,'Raw Data in Target'!$B:$B,'Target Working'!$E174) -> #REF!
B175: 3400636 | C175: D0129 | D175: Tanveer Traders | E175: D0129OB1 | F175: Order Booker | G175: Shabbir Hussain Sajid | H175: 3000005990 | I175: MSKU00274 | J175: Panda | K175: SKU00535 | L175: Tegra Panda soft | M175: =SUMIFS('Raw Data in Target'!#REF!,'Raw Data in Target'!$J:$J,'Target Working'!$K175,'Raw Data in Target'!$B:$B,'Target Working'!$E175) -> #REF!
B176: 3400636 | C176: D0129 | D176: Tanveer Traders | E176: D0129OB1 | F176: Order Booker | G176: Shabbir Hussain Sajid | H176: 3000006112 | I176: MSKU00324 | J176: YES SUPER PLUS PAD 10PCS | K176: SKU00670 | L176: YES SUPER PLUS PAD 10PCS | M176: =SUMIFS('Raw Data in Target'!#REF!,'Raw Data in Target'!$J:$J,'Target Working'!$K176,'Raw Data in Target'!$B:$B,'Target Working'!$E176) -> #REF!
B177: 3400636 | C177: D0129 | D177: Tanveer Traders | E177: D0129OB1 | F177: Order Booker | G177: Shabbir Hussain Sajid | H177: 3000000059 | I177: MSKU00343 | J177: Truly Adult Diapers Sachet 3-M | K177: SKU00695 | L177: Truly Adult Diapers ECO 10 (3M) | M177: =SUMIFS('Raw Data in Target'!#REF!,'Raw Data in Target'!$J:$J,'Target Working'!$K177,'Raw Data in Target'!$B:$B,'Target Working'!$E177) -> #REF!
B178: 3400636 | C178: D0129 | D178: Tanveer Traders | E178: D0129OB1 | F178: Order Booker | G178: Shabbir Hussain Sajid | H178: 3000006443 | I178: MSKU00018 | J178: Safa Care Wipes Deluxe | K178: SKU00698 | L178: Safa Care Wipes Deluxe 60 Pcs x 48 | M178: =SUMIFS('Raw Data in Target'!#REF!,'Raw Data in Target'!$J:$J,'Target Working'!$K178,'Raw Data in Target'!$B:$B,'Target Working'!$E178) -> #REF!
B179: 3400636 | C179: D0129 | D179: Tanveer Traders | E179: D0129OB2 | F179: Order Booker | G179: Ali Hasnain | H179: 3000000044 | I179: MSKU00024 | J179: Mimi Papa Adult Diapers ECO 2-S | K179: SKU00269 | L179: Mimi Papa Adult Diapers ECO 10 (2-S) | M179: =SUMIFS('Raw Data in Target'!#REF!,'Raw Data in Target'!$J:$J,'Target Working'!$K179,'Raw Data in Target'!$B:$B,'Target Working'!$E179) -> #REF!
B180: 3400636 | C180: D0129 | D180: Tanveer Traders | E180: D0129OB2 | F180: Order Booker | G180: Ali Hasnain | H180: 3000000349 | I180: MSKU00185 | J180: Bona Magic Wipes Deluxe 72 Pcs | K180: SKU00292 | L180: Bona Magic Wipes Deluxe 72 Pcs | M180: =SUMIFS('Raw Data in Target'!#REF!,'Raw Data in Target'!$J:$J,'Target Working'!$K180,'Raw Data in Target'!$B:$B,'Target Working'!$E180) -> #REF!
B181: 3400636 | C181: D0129 | D181: Tanveer Traders | E181: D0129OB2 | F181: Order Booker | G181: Ali Hasnain | H181: 3000003335 | I181: MSKU00152 | J181: Bona Magic Baby Diapers ECO 2-S | K181: SKU00300 | L181: Bona Magic Baby Diapers ECO 44 (2-S) | M181: =SUMIFS('Raw Data in Target'!#REF!,'Raw Data in Target'!$J:$J,'Target Working'!$K181,'Raw Data in Target'!$B:$B,'Target Working'!$E181) -> #REF!
B182: 3400636 | C182: D0129 | D182: Tanveer Traders | E182: D0129OB2 | F182: Order Booker | G182: Ali Hasnain | H182: 3000006014 | I182: MSKU00277 | J182: Body Razor | K182: SKU00530 | L182: Tegra Jet Body | M182: =SUMIFS('Raw Data in Target'!#REF!,'Raw Data in Target'!$J:$J,'Target Working'!$K182,'Raw Data in Target'!$B:$B,'Target Working'!$E182) -> #REF!
... B210: 3400636 | C210: D0129 | D210: Tanveer Traders | E210: D0129OB6 | F210: Order Booker | G210: Ali Imam | H210: 3000006443 | I210: MSKU00018 | J210: Safa Care Wipes Deluxe | K210: SKU00698 | L210: Safa Care Wipes Deluxe 60 Pcs x 48 | M210: =SUMIFS('Raw Data in Target'!#REF!,'Raw Data in Target'!$J:$J,'Target Working'!$K210,'Raw Data in Target'!$B:$B,'Target Working'!$E210) -> #REF!
B211: D0129 | C211: D0131 | D211: Ahmed Trader | E211: D0131OB1 | F211: Order Booker | G211: Ali Hasnain | H211: 3000000044 | I211: MSKU00024 | J211: Mimi Papa Adult Diapers ECO 2-S | K211: SKU00269 | L211: Mimi Papa Adult Diapers ECO 10 (2-S) | M211: =SUMIFS('Raw Data in Target'!#REF!,'Raw Data in Target'!$J:$J,'Target Working'!$K211,'Raw Data in Target'!$B:$B,'Target Working'!$E211) -> #REF!
B212: D0129 | C212: D0131 | D212: Ahmed Trader | E212: D0131OB1 | F212: Order Booker | G212: Ali Hasnain | H212: 3000000349 | I212: MSKU00185 | J212: Bona Magic Wipes Deluxe 72 Pcs | K212: SKU00292 | L212: Bona Magic Wipes Deluxe 72 Pcs | M212: =SUMIFS('Raw Data in Target'!#REF!,'Raw Data in Target'!$J:$J,'Target Working'!$K212,'Raw Data in Target'!$B:$B,'Target Working'!$E212) -> #REF!
B213: D0129 | C213: D0131 | D213: Ahmed Trader | E213: D0131OB1 | F213: Order Booker | G213: Ali Hasnain | H213: 3000003335 | I213: MSKU00152 | J213: Bona Magic Baby Diapers ECO 2-S | K213: SKU00300 | L213: Bona Magic Baby Diapers ECO 44 (2-S) | M213: =SUMIFS('Raw Data in Target'!#REF!,'Raw Data in Target'!$J:$J,'Target Working'!$K213,'Raw Data in Target'!$B:$B,'Target Working'!$E213) -> #REF!
B214: D0129 | C214: D0131 | D214: Ahmed Trader | E214: D0131OB1 | F214: Order Booker | G214: Ali Hasnain | H214: 3000006014 | I214: MSKU00277 | J214: Body Razor | K214: SKU00530 | L214: Tegra Jet Body | M214: =SUMIFS('Raw Data in Target'!#REF!,'Raw Data in Target'!$J:$J,'Target Working'!$K214,'Raw Data in Target'!$B:$B,'Target Working'!$E214) -> #REF!
B215: D0129 | C215: D0131 | D215: Ahmed Trader | E215: D0131OB1 | F215: Order Booker | G215: Ali Hasnain | H215: 3000005990 | I215: MSKU00274 | J215: Panda | K215: SKU00535 | L215: Tegra Panda soft | M215: =SUMIFS('Raw Data in Target'!#REF!,'Raw Data in Target'!$J:$J,'Target Working'!$K215,'Raw Data in Target'!$B:$B,'Target Working'!$E215) -> #REF!
B216: D0129 | C216: D0131 | D216: Ahmed Trader | E216: D0131OB1 | F216: Order Booker | G216: Ali Hasnain | H216: 3000006112 | I216: MSKU00324 | J216: YES SUPER PLUS PAD 10PCS | K216: SKU00670 | L216: YES SUPER PLUS PAD 10PCS | M216: =SUMIFS('Raw Data in Target'!#REF!,'Raw Data in Target'!$J:$J,'Target Working'!$K216,'Raw Data in Target'!$B:$B,'Target Working'!$E216) -> #REF!
B217: D0129 | C217: D0131 | D217: Ahmed Trader | E217: D0131OB1 | F217: Order Booker | G217: Ali Hasnain | H217: 3000000059 | I217: MSKU00343 | J217: Truly Adult Diapers Sachet 3-M | K217: SKU00695 | L217: Truly Adult Diapers ECO 10 (3M) | M217: =SUMIFS('Raw Data in Target'!#REF!,'Raw Data in Target'!$J:$J,'Target Working'!$K217,'Raw Data in Target'!$B:$B,'Target Working'!$E217) -> #REF!
B218: D0129 | C218: D0131 | D218: Ahmed Trader | E218: D0131OB1 | F218: Order Booker | G218: Ali Hasnain | H218: 3000006443 | I218: MSKU00018 | J218: Safa Care Wipes Deluxe | K218: SKU00698 | L218: Safa Care Wipes Deluxe 60 Pcs x 48 | M218: =SUMIFS('Raw Data in Target'!#REF!,'Raw Data in Target'!$J:$J,'Target Working'!$K218,'Raw Data in Target'!$B:$B,'Target Working'!$E218) -> #REF!
B219: D0129 | C219: D0131 | D219: Ahmed Trader | E219: D0131OB2 | F219: Order Booker | G219: Muneeb Ahmad | H219: 3000000044 | I219: MSKU00024 | J219: Mimi Papa Adult Diapers ECO 2-S | K219: SKU00269 | L219: Mimi Papa Adult Diapers ECO 10 (2-S) | M219: =SUMIFS('Raw Data in Target'!#REF!,'Raw Data in Target'!$J:$J,'Target Working'!$K219,'Raw Data in Target'!$B:$B,'Target Working'!$E219) -> #REF!
B220: D0129 | C220: D0131 | D220: Ahmed Trader | E220: D0131OB2 | F220: Order Booker | G220: Muneeb Ahmad | H220: 3000000349 | I220: MSKU00185 | J220: Bona Magic Wipes Deluxe 72 Pcs | K220: SKU00292 | L220: Bona Magic Wipes Deluxe 72 Pcs | M220: =SUMIFS('Raw Data in Target'!#REF!,'Raw Data in Target'!$J:$J,'Target Working'!$K220,'Raw Data in Target'!$B:$B,'Target Working'!$E220) -> #REF!
B221: D0129 | C221: D0131 | D221: Ahmed Trader | E221: D0131OB2 | F221: Order Booker | G221: Muneeb Ahmad | H221: 3000003335 | I221: MSKU00152 | J221: Bona Magic Baby Diapers ECO 2-S | K221: SKU00300 | L221: Bona Magic Baby Diapers ECO 44 (2-S) | M221: =SUMIFS('Raw Data in Target'!#REF!,'Raw Data in Target'!$J:$J,'Target Working'!$K221,'Raw Data in Target'!$B:$B,'Target Working'!$E221) -> #REF!
B222: D0129 | C222: D0131 | D222: Ahmed Trader | E222: D0131OB2 | F222: Order Booker | G222: Muneeb Ahmad | H222: 3000006014 | I222: MSKU00277 | J222: Body Razor | K222: SKU00530 | L222: Tegra Jet Body | M222: =SUMIFS('Raw Data in Target'!#REF!,'Raw Data in Target'!$J:$J,'Target Working'!$K222,'Raw Data in Target'!$B:$B,'Target Working'!$E222) -> #REF!
...

Sheet Pivot
A1: BU | B1: (Multiple Items)
A3: Manager name | B3: Salesflo AppUser Code | C3: Trim Distributor Code | D3: AppUser Name | E3: Category Name | F3: Brand Name | G3: Name | H3: Sum of Cases | I3: Sum of Units | J3: Sum of Value
A4: Ali Niazi | B4: 9000000218 | C4: D0441 | D4: Saqlain Haider | E4: Adult Diapers | F4: Sofped | G4: Javed | H4: 20.28 | I4: 2028 | J4: 250996.33
A5: Ali Niazi | B5: 9000000218 | C5: D0441 | D5: Saqlain Haider | E5: Adult Pants | F5: Sofped | G5: Javed | H5: 1.05625 | I5: 105.625 | J5: 140.98651
A6: Ali Niazi | B6: 9000000218 | C6: D0441 | D6: Saqlain Haider | E6: Baby Diapers | F6: Momse | G6: Javed | H6: 97.2 | I6: 27993.6 | J6: 797253.85
A7: Ali Niazi | B7: 9000000218 | C7: D0441 | D7: Saqlain Haider | E7: Pants | F7: Momse | G7: Javed | H7: 26.4 | I7: 5068.8 | J7: 219274.22
A8: Ali Niazi | B8: 9000000218 | C8: D0441 | D8: Saqlain Haider | E8: Wipes | F8: Momse | G8: Javed | H8: 15.12 | I8: 362.88 | J8: 112835.16
A9: Ali Niazi | B9: 9000000218 | C9: D0441 | D9: Saqlain Haider | E9: Wipes | F9: Nazuk | G9: Javed | H9: 14.586 | I9: 350.064 | J9: 27496.386
A10: Ali Niazi | B10: 9000001386 | C10: D0441 | D10: Zain Ul Abadin | E10: Adult Diapers | F10: Sofped | G10: Javed | H10: 27.3 | I10: 2730 | J10: 337879.67
A11: Ali Niazi | B11: 9000001386 | C11: D0441 | D11: Zain Ul Abadin | E11: Adult Pants | F11: Sofped | G11: Javed | H11: 1.70625 | I11: 170.625 | J11: 227.74745
A12: Ali Niazi | B12: 9000001386 | C12: D0441 | D12: Zain Ul Abadin | E12: Baby Diapers | F12: Momse | G12: Javed | H12: 81 | I12: 23328 | J12: 664378.21
A13: Ali Niazi | B13: 9000001386 | C13: D0441 | D13: Zain Ul Abadin | E13: Pants | F13: Momse | G13: Javed | H13: 20.625 | I13: 3960 | J13: 171307.98
A14: Ali Niazi | B14: 9000001386 | C14: D0441 | D14: Zain Ul Abadin | E14: Sanitary Napkin | F14: Nofea | G14: Javed | H14: 71.7825 | I14: 53014.5 | J14: 126405.82
A15: Ali Niazi | B15: 9000001386 | C15: D0441 | D15: Zain Ul Abadin | E15: Wipes | F15: Momse | G15: Javed | H15: 15.3 | I15: 367.2 | J15: 114178.44
... A625: Ali Niazi | B625: DO520OB1 | C625: D0520 | D625: Haider Maqbool | E625: Baby Diapers | F625: Bona Magic | G625: Raza (Ali Nazi) | H625: 150 | I625: 52800 | J625: 1314712.2
A626: Ali Niazi | B626: Trading | D626: Trading | E626: Baby Diapers | F626: Ono | G626: ali | H626: 2000 | I626: 0 | J626: 11738300
A627: Ali Niazi | B627: Trading | D627: Trading | E627: Baby Diapers | F627: Sorex | G627: ali | H627: 500 | I627: 0 | J627: 3227890
A628: Amir Tayyab | B628: D0030OB1 | C628: D0030 | D628: Ahmed Nasir | E628: Adult Diapers | F628: Safa Care | G628: Nomani | H628: 12 | I628: 1200 | J628: 121854.58
A629: Amir Tayyab | B629: D0030OB1 | C629: D0030 | D629: Ahmed Nasir | E629: Adult Diapers | F629: Truly | G629: Nomani | H629: 9 | I629: 900 | J629: 67924.213
A630: Amir Tayyab | B630: D0030OB1 | C630: D0030 | D630: Ahmed Nasir | E630: Baby Diapers | F630: Bona Magic | G630: Nomani | H630: 115 | I630: 40480 | J630: 1007946
A631: Amir Tayyab | B631: D0030OB1 | C631: D0030 | D631: Ahmed Nasir | E631: Oral Care | F631: Tegra TB | G631: Nomani | H631: 4 | I631: 576 | J631: 22101.955
A632: Amir Tayyab | B632: D0030OB1 | C632: D0030 | D632: Ahmed Nasir | E632: Pants | F632: Bona Magic | G632: Nomani | H632: 23 | I632: 8280 | J632: 209617.04
A633: Amir Tayyab | B633: D0030OB1 | C633: D0030 | D633: Ahmed Nasir | E633: Personal Care | F633: Tegra RZ | G633: Nomani | H633: 3 | I633: 864 | J633: 14560.288
A634: Amir Tayyab | B634: D0030OB1 | C634: D0030 | D634: Ahmed Nasir | E634: Sanitary Napkin | F634: YES | G634: Nomani | H634: 12 | I634: 5760 | J634: 59915.824
A635: Amir Tayyab | B635: D0030OB1 | C635: D0030 | D635: Ahmed Nasir | E635: Wipes | F635: Bona Magic | G635: Nomani | H635: 25 | I635: 600 | J635: 89786.832
A636: Amir Tayyab | B636: D0030OB1 | C636: D0030 | D636: Ahmed Nasir | E636: Wipes | F636: Safa Care | G636: Nomani | H636: 8 | I636: 384 | J636: 8031.319
A637: Amir Tayyab | B637: D0030OB2 | C637: D0030 | D637: Muzaffar Yaseen | E637: Adult Diapers | F637: Safa Care | G637: Nomani | H637: 11 | I637: 1100 | J637: 111700.03
A638: Amir Tayyab | B638: D0030OB2 | C638: D0030 | D638: Muzaffar Yaseen | E638: Adult Diapers | F638: Truly | G638: Nomani | H638: 8 | I638: 800 | J638: 60377.078
A639: Amir Tayyab | B639: D0030OB2 | C639: D0030 | D639: Muzaffar Yaseen | E639: Baby Diapers | F639: Bona Magic | G639: Nomani | H639: 125 | I639: 44000 | J639: 1095593.5
... A1875: Arsalan Khan | B1875: D0517OB1 | C1875: D0517 | D1875: Muhammad Umar | E1875: Wipes | F1875: Safa Care | G1875: Arsalan | H1875: 7 | I1875: 336 | J1875: 7027.4041
A1876: Arsalan Khan | B1876: Trading | D1876: Trading | E1876: Baby Diapers | F1876: Ono | G1876: Arsalan Khan | H1876: 3000 | I1876: 0 | J1876: 17607450
A1877: Arsalan Khan | B1877: Trading | D1877: Trading | E1877: Baby Diapers | F1877: Sorex | G1877: Arsalan Khan | H1877: 500 | I1877: 0 | J1877: 3227890
A1878: Atif Akram | B1878: 9000002829 | C1878: D0134 | D1878: Muhammad Zeeshan | E1878: Baby Diapers | F1878: Bona Magic | G1878: Atif (FSD) | H1878: 100 | I1878: 35200 | J1878: 876474.82
A1879: Atif Akram | B1879: 9000002829 | C1879: D0134 | D1879: Muhammad Zeeshan | E1879: Wipes | F1879: Bona Magic | G1879: Atif (FSD) | H1879: 5 | I1879: 120 | J1879: 17957.366
A1880: Atif Akram | B1880: 9000003138 | C1880: D0355 | D1880: M.Burhan | E1880: Adult Diapers | F1880: Safa Care | G1880: Atif (FSD) | H1880: 3 | I1880: 300 | J1880: 30463.644
A1881: Atif Akram | B1881: 9000003138 | C1881: D0355 | D1881: M.Burhan | E1881: Adult Diapers | F1881: Sofped | G1881: Atif (FSD) | H1881: 4 | I1881: 400 | J1881: 49506.179
A1882: Atif Akram | B1882: 9000003138 | C1882: D0355 | D1882: M.Burhan | E1882: Adult Diapers | F1882: Truly | G1882: Atif (FSD) | H1882: 1 | I1882: 100 | J1882: 7547.1347
A1883: Atif Akram | B1883: 9000003138 | C1883: D0355 | D1883: M.Burhan | E1883: Baby Diapers | F1883: Bona Magic | G1883: Atif (FSD) | H1883: 110 | I1883: 38720 | J1883: 964122.31
A1884: Atif Akram | B1884: 9000003138 | C1884: D0355 | D1884: M.Burhan | E1884: Sanitary Napkin | F1884: YES | G1884: Atif (FSD) | H1884: 4 | I1884: 1920 | J1884: 19971.941
A1885: Atif Akram | B1885: 9000003138 | C1885: D0355 | D1885: M.Burhan | E1885: Wipes | F1885: Bona Magic | G1885: Atif (FSD) | H1885: 4 | I1885: 96 | J1885: 14365.893
...

Sheet Distributor Mapping
A1: DistributorCode | B1: Distributor Sap Code | C1: Distributor Sap Name | D1: Channel | E1: New Region | F1: Area | G1: Sub Area | H1: Territory | I1: BU Model | J1: Sales Manager | K1: New Region | L1: Type | M1: Remarks | N1: Segment
A2: D0001 | B2: 3400081 | C2: Ayan Trading | D2: Bona Papa GT | E2: KHI Bona & Super Plus | F2: Karachi | G2: Gulistan-e-Johar | H2: Gulistan-e-Johar | I2: Bona super & plus | J2: Farhan | K2: KHI Bona & Super Plus | L2: Direct Distributor | M2: Top Town | N2: General Trade
A3: D0002 | B3: 3400088 | C3: Sufyan Traders | D3: Bona Papa GT | E3: KHI Bona & Super Plus | F3: Karachi | G3: Karimabad | H3: Karimabad | I3: Bona super & plus | J3: Farhan | K3: KHI Bona & Super Plus | L3: Direct Distributor | M3: Top Town | N3: General Trade
A4: D0003 | B4: 3400089 | C4: Usman Trader | D4: Bona Papa GT | E4: KHI Bona & Super Plus | F4: Karachi | G4: North Karachi | H4: North Karachi | I4: Bona super & plus | J4: Farhan | K4: KHI Bona & Super Plus | L4: Direct Distributor | M4: Top Town | N4: General Trade
A5: D0005 | B5: 3400091 | C5: K.F Traders | D5: Bona Papa GT | E5: KHI Bona & Super Plus | F5: Karachi | G5: Baldia Town | H5: Baldia Town | I5: Bona super & plus | J5: Farhan | K5: KHI Bona & Super Plus | L5: Direct Distributor | M5: Top Town | N5: General Trade
A6: D0007 | B6: 3400084 | C6: Alishba Traders | D6: Bona Papa GT | E6: KHI Bona & Super Plus | F6: Karachi | G6: Old City Area | H6: Old City Area | I6: Bona super & plus | J6: Farhan | K6: KHI Bona & Super Plus | L6: Direct Distributor | M6: Top Town | N6: General Trade
A7: D0008 | B7: 3400083 | C7: Qadri 2 | D7: Bona Papa GT | E7: KHI Bona & Super Plus | F7: Karachi | G7: Shah faisal | H7: Shah faisal | I7: Bona super & plus | J7: Farhan | K7: KHI Bona & Super Plus | L7: Direct Distributor | M7: Top Town | N7: General Trade
A8: D0009 | B8: 3400085 | C8: M.R.S Global | D8: Bona Papa GT | E8: KHI Bona & Super Plus | F8: Karachi | G8: Jodia Bazar | H8: Jodia Bazar | I8: Bona super & plus | J8: Farhan | K8: KHI Bona & Super Plus | L8: Direct Distributor | M8: Top Town | N8: General Trade
A9: D0011 | B9: 3400086 | C9: Memon Traders | D9: Bona Papa GT | E9: KHI Bona & Super Plus | F9: Karachi | G9: Gulshan-e-Hadeed | H9: Gulshan-e-Hadeed | I9: Bona super & plus | J9: Farhan | K9: KHI Bona & Super Plus | L9: Direct Distributor | M9: Top Town | N9: General Trade
A10: D0012 | B10: 3400082 | C10: Qadri Traders 1 | D10: Bona Papa GT | E10: KHI Bona & Super Plus | F10: Karachi | G10: Korangi | H10: Korangi | I10: Bona super & plus | J10: Farhan | K10: KHI Bona & Super Plus | L10: Direct Distributor | M10: Top Town | N10: General Trade
A11: D0013 | B11: D0013 | C11: Ab Trader | D11: Nana Smarty GT | E11: Multan Region | F11: Lahore | G11: Sabzazar | H11: Sabzazar | I11: Nana Smarty | J11: Adeel Yasin | K11: Multan Region | L11: Sub Distributor | M11: Top Town | N11: General Trade
A12: D0014 | B12: D0014 | C12: Impact Marketing | D12: Nana Smarty GT | E12: Lahore Region | F12: Lahore | G12: Lahore | H12: Lahore | I12: Nana Smarty | J12: Adeel Yasin | K12: Lahore Region | L12: Sub Distributor | M12: Top Town | N12: General Trade
A13: D0015 | B13: D0015 | C13: Tawakal Trader | D13: GT | E13: Lahore Region | F13: Lahore | G13: Lahore | H13: Lahore | I13: unassigned | J13: unassigned | K13: Lahore Region | L13: Direct Distributor | N13: General Trade
A14: D0016 | B14: D0016 | C14: Abdur Rehman Trader | D14: GT | E14: Lahore Region | F14: Lahore | G14: Lahore | H14: Lahore | I14: unassigned | J14: unassigned | K14: Lahore Region | L14: Direct Distributor | N14: General Trade
A15: D0017 | B15: D0017 | C15: Talha Trader Lahore Nana | D15: GT | E15: Lahore Region | F15: Lahore | G15: Lahore | H15: Lahore | I15: unassigned | J15: unassigned | K15: Lahore Region | L15: Direct Distributor | N15: General Trade
A16: D0018 | B16: D0018 | C16: Rehbar Enterprises | D16: GT | E16: Lahore Region | F16: Lahore | G16: Lahore | H16: Lahore | I16: unassigned | J16: unassigned | K16: Lahore Region | L16: Sub Distributor | N16: General Trade
A17: D0019 | B17: 3400246 | C17: Ahsan Marketing | D17: Nana Smarty GT | E17: Lahore Region | F17: Lahore | G17: Lahore | H17: Lahore | I17: Nana Smarty | J17: Adeel Yasin | K17: Lahore Region | L17: Direct Distributor | N17: General Trade
A18: D0020 | B18: D0020 | C18: Al- Hilal Agencies | D18: Nana Smarty GT | E18: Multan Region | F18: Multan | G18: Multan | H18: Multan | I18: Nana Smarty | J18: Adeel Yasin | K18: Multan Region | L18: Sub Distributor | M18: Top Town | N18: General Trade
A19: D0021 | B19: 3400530 | C19: Bilal Distributor | D19: Modern Trade | E19: LMT South | F19: Karachi | G19: Karachi | H19: Karachi | I19: LMT | J19: Mustafa Nasir | K19: LMT South | L19: Direct Distributor | M19: Top Town | N19: Modern Trade & KA
A20: D0023 | B20: 3400837 | C20: Raheem Gul Traders | D20: Nana Smarty GT | E20: Peshawar Region | F20: Peshawar | G20: Mingora | H20: Mingora | I20: Nana Smarty | J20: Adeel Yasin | K20: Peshawar Region | L20: Direct Distributor | N20: General Trade
A21: D0024 | B21: 3400067 | C21: Ankd Group | D21: Nana Smarty GT | E21: South Magic | F21: Karachi | G21: Korangi Zaman Town | H21: Korangi Zaman Town | I21: Nana Smarty | J21: Adeel Yasin | K21: South Magic | L21: Direct Distributor | M21: Top Town | N21: General Trade
A22: D0026 | B22: 3400066 | C22: Un Traders | D22: Nana Smarty GT | E22: South Magic | F22: Karachi | G22: Orangi Town | H22: Orangi Town | I22: Nana Smarty | J22: Adeel Yasin | K22: South Magic | L22: Direct Distributor | M22: Top Town | N22: General Trade
A23: D0027 | B23: 3400065 | C23: Ubi Traders | D23: Nana Smarty GT | E23: South Magic | F23: Karachi | G23: Korangi Causeway | H23: Korangi Causeway | I23: Nana Smarty | J23: Adeel Yasin | K23: South Magic | L23: Direct Distributor | M23: Top Town | N23: General Trade
A24: D0028 | B24: D0028 | C24: M Iqbal Traders | D24: Bona Papa GT | E24: South Plus & Super | F24: Larkana | G24: Larkana | H24: Larkana | I24: Bona super & plus | J24: Amir Tayyab | K24: South Plus & Super | L24: Sub Distributor | M24: Top Town | N24: General Trade
A25: D0029 | B25: 3400039 | C25: Aleena Star Enterprises | D25: GT | E25: South Plus & Super | F25: Hyderabad | G25: Hyderabad | H25: Hyderabad | I25: unassigned | J25: unassigned | K25: South Plus & Super | L25: Direct Distributor | N25: General Trade
A26: D0030 | B26: 3400011 | C26: Ayan Trading | D26: Bona Papa GT | E26: South Plus & Super | F26: Karachi | G26: Gulistan e Johar | H26: Gulistan e Johar | I26: Bona Magic | J26: Amir tayyab | K26: South Plus & Super | L26: Direct Distributor | M26: Top Town | N26: General Trade
A27: D0031 | B27: 3400039 | C27: Aleena Star Enterprises | D27: Bona Papa GT | E27: South Plus & Super | F27: Hyderabad | G27: Hyderabad | H27: Hyderabad | I27: Bona super & plus | J27: Amir tayyab | K27: South Plus & Super | L27: Master Distributor | N27: General Trade
A28: D0038 | B28: 3400043 | C28: Star Enterprises | D28: Bona Papa GT | E28: South Plus & Super | F28: Hyderabad | G28: Hyderabad | H28: Hyderabad | I28: Bona super & plus | J28: Amir tayyab | K28: South Plus & Super | L28: Master Distributor | N28: General Trade
A29: D0039 | B29: 3400239 | C29: Khan Traders | D29: Nana Smarty GT | E29: Multan Region | F29: Faisalabad | G29: Sargodha | H29: Sargodha | I29: Nana Smarty | J29: Adeel Yasin | K29: Multan Region | L29: Master Distributor | N29: General Trade
A30: D0041 | B30: D0041 | C30: M Muzammil Traders | D30: Bona Papa GT | E30: South Plus & Super | F30: Sukkur | G30: Sukkur | H30: Sukkur | I30: Bona super & plus | J30: Amir Tayyab | K30: South Plus & Super | L30: Sub Distributor | M30: Top Town | N30: General Trade
A31: D0042 | B31: 3400595 | C31: Rk Traders | D31: Nana Smarty GT | E31: Peshawar Region | F31: Peshawar | G31: Peshawar | H31: Peshawar | I31: Nana Smarty | J31: Adeel Yasin | K31: Peshawar Region | L31: Master Distributor | N31: General Trade
A32: D0043 | B32: 3400846 | C32: Sm Traders | D32: Nana Smarty GT | E32: Lahore Region | F32: Sialkot | G32: Sialkot | H32: Sialkot | I32: Nana Smarty | J32: Adeel Yasin | K32: Lahore Region | L32: Master Distributor | N32: General Trade
A33: D0044 | B33: 3400494 | C33: Mm Traders | D33: GT | E33: Lahore Region | F33: Gujranwala | G33: Gujranwala | H33: Gujranwala | I33: unassigned | J33: unassigned | K33: Lahore Region | L33: Direct Distributor | N33: General Trade
A34: D0045 | B34: D0045 | C34: Choudary Brothers | D34: Nana Smarty GT | E34: Lahore Region | F34: Gujranwala | G34: Gujranwala | H34: Kangniwala | I34: Nana Smarty | J34: Adeel Yasin | K34: Lahore Region | L34: Sub Distributor | M34: Top Town | N34: General Trade
A35: D0046 | B35: 3400234 | C35: A H Traders | D35: GT | E35: Islamabad Region | F35: Islamabad | G35: Rawalpindi | H35: Rawalpindi | I35: unassigned | J35: unassigned | K35: Islamabad Region | L35: Master Distributor | N35: General Trade
A36: D0047 | B36: 3400557 | C36: Ali Naeem & Company | D36: Bona Papa GT | E36: Multan Region | F36: Multan | G36: Bahawal Pur | H36: Bahawal Pur | I36: Bona Magic | J36: Atif Akram | K36: Multan Region | L36: Master Distributor | N36: General Trade
A37: D0048 | B37: D0048 | C37: Shoaib Agencies | D37: GT | E37: Islamabad Region | F37: Islamabad | G37: Rawalpindi | H37: Rawalpindi | I37: unassigned | J37: unassigned | K37: Islamabad Region | L37: Sub Distributor | N37: General Trade
A38: D0049 | B38: D0049 | C38: Khan Enterprises | D38: Nana Smarty GT | E38: Islamabad Region | F38: Islamabad | G38: Rawalpindi | H38: Rawalpindi | I38: Nana Smarty | J38: Adeel Yasin | K38: Islamabad Region | L38: Sub Distributor | N38: General Trade
A39: D0050 | B39: D0050 | C39: Azan Traders | D39: GT | E39: Islamabad Region | F39: Islamabad | G39: Rawalpindi | H39: Rawalpindi | I39: unassigned | J39: unassigned | K39: Islamabad Region | L39: Sub Distributor | N39: General Trade
A40: D0051 | B40: D0051 | C40: Fahad Medicine | D40: GT | E40: Peshawar Region | F40: Peshawar | G40: Peshawar | H40: Kohat | I40: unassigned | J40: unassigned | K40: Peshawar Region | L40: Sub Distributor | N40: General Trade
...

Sheet Raw Data in Target
A1: Name | B1: Salesflo AppUser Code | C1: AppUser Name | D1: OB Status | E1: Dist Code | F1: Dist Name | G1: Brand | H1: Category | I1: Key | J1: SKU Code | K1: Cases | L1: Sku Active | M1: Pack Size | N1: Units | O1: Value | P1: Trim Distributor Code | Q1: Sap Code | R1: SKU Code Status | S1: Booker Code Status | T1: Manager name | U1: BU | V1: Category Name | W1: Brand Name | X1: Distributor Status
A2: Ali Nazi | B2: D0013OB10 | C2: Mubeen Amir | D2: Active | E2: D0013 | F2: Ab Trader | G2: NANA SMARTY | H2: DIAPER | I2: NANA SMARTYDIAPER | J2: SKU00323 | K2: 140 | L2: Active | M2: =Table1[[#This Row],[Cases]]*Table1[[#This Row],[Pack Size]] -> 0 | N2: =Table1[[#This Row],[Cases]]*Table1[[#This Row],[Pack Size]] -> 56000 | O2: =IFERROR(VLOOKUP(Table1[[#This Row],[SKU Code]],'SKU Size'!$G:$H,2,FALSE),0)*Table1[[#This Row],[Cases]] -> 1267265.2 | P2: =TRIM(E2) -> D0013 | Q2: =IFERROR(VLOOKUP(Table1[[#This Row],[Trim Distributor Code]],Sheet1!$N:$O,2,FALSE),0) -> D0381 | R2: =IFERROR(VLOOKUP(Table1[[#This Row],[Salesflo AppUser Code]],HIE!$A:$B,2,FALSE),0) -> 0 | S2: =IFERROR(VLOOKUP(Table1[[#This Row],[Salesflo AppUser Code]],HIE!$A:$B,2,FALSE),0) -> 0 | T2: Ali Niazi | U2: Multan | V2: Baby Diapers | W2: NaNa | X2: =IFERROR(VLOOKUP( Table1[[#This Row],[Trim Distributor Code]],Sheet1!$A:$J,10,FALSE),0) -> Active
A3: Ali Nazi | B3: D0013OB10 | C3: Mubeen Amir | D3: Active | E3: D0013 | F3: Ab Trader | G3: NANA SMARTY | H3: PANTS | I3: NANA SMARTYPANTS | J3: SKU00344 | K3: 2.5 | L3: Active | M3: =Table1[[#This Row],[Cases]]*Table1[[#This Row],[Pack Size]] -> 0 | N3: =Table1[[#This Row],[Cases]]*Table1[[#This Row],[Pack Size]] -> 960 | O3: =IFERROR(VLOOKUP(Table1[[#This Row],[SKU Code]],'SKU Size'!$G:$H,2,FALSE),0)*Table1[[#This Row],[Cases]] -> 23298.474 | P3: =TRIM(E3) -> D0013 | Q3: =IFERROR(VLOOKUP(Table1[[#This Row],[Trim Distributor Code]],Sheet1!$N:$O,2,FALSE),0) -> D0381 | R3: =IFERROR(VLOOKUP(Table1[[#This Row],[Salesflo AppUser Code]],HIE!$A:$B,2,FALSE),0) -> 0 | S3: =IFERROR(VLOOKUP(Table1[[#This Row],[Salesflo AppUser Code]],HIE!$A:$B,2,FALSE),0) -> 0 | T3: Ali Niazi | U3: Multan | V3: Pants | W3: NaNa | X3: =IFERROR(VLOOKUP( Table1[[#This Row],[Trim Distributor Code]],Sheet1!$A:$J,10,FALSE),0) -> Active
A4: Ali Nazi | B4: D0013OB10 | C4: Mubeen Amir | D4: Active | E4: D0013 | F4: Ab Trader | G4: NANA SMARTY | H4: WIPES | I4: NANA SMARTYWIPES | J4: SKU00342 | K4: 5 | L4: Active | M4: =Table1[[#This Row],[Cases]]*Table1[[#This Row],[Pack Size]] -> 0 | N4: =Table1[[#This Row],[Cases]]*Table1[[#This Row],[Pack Size]] -> 120 | O4: =IFERROR(VLOOKUP(Table1[[#This Row],[SKU Code]],'SKU Size'!$G:$H,2,FALSE),0)*Table1[[#This Row],[Cases]] -> 17220.323 | P4: =TRIM(E4) -> D0013 | Q4: =IFERROR(VLOOKUP(Table1[[#This Row],[Trim Distributor Code]],Sheet1!$N:$O,2,FALSE),0) -> D0381 | R4: =IFERROR(VLOOKUP(Table1[[#This Row],[Salesflo AppUser Code]],HIE!$A:$B,2,FALSE),0) -> 0 | S4: =IFERROR(VLOOKUP(Table1[[#This Row],[Salesflo AppUser Code]],HIE!$A:$B,2,FALSE),0) -> 0 | T4: Ali Niazi | U4: Multan | V4: Wipes | W4: NaNa | X4: =IFERROR(VLOOKUP( Table1[[#This Row],[Trim Distributor Code]],Sheet1!$A:$J,10,FALSE),0) -> Active
A5: Ali Nazi | B5: D0013OB10 | C5: Mubeen Amir | D5: Active | E5: D0013 | F5: Ab Trader | G5: DADU | H5: ADULT DIAPER | I5: DADUADULT DIAPER | J5: SKU00340 | K5: 10 | L5: Active | M5: =Table1[[#This Row],[Cases]]*Table1[[#This Row],[Pack Size]] -> 0 | N5: =Table1[[#This Row],[Cases]]*Table1[[#This Row],[Pack Size]] -> 1000 | O5: =IFERROR(VLOOKUP(Table1[[#This Row],[SKU Code]],'SKU Size'!$G:$H,2,FALSE),0)*Table1[[#This Row],[Cases]] -> 101712.54 | P5: =TRIM(E5) -> D0013 | Q5: =IFERROR(VLOOKUP(Table1[[#This Row],[Trim Distributor Code]],Sheet1!$N:$O,2,FALSE),0) -> D0381 | R5: =IFERROR(VLOOKUP(Table1[[#This Row],[Salesflo AppUser Code]],HIE!$A:$B,2,FALSE),0) -> 0 | S5: =IFERROR(VLOOKUP(Table1[[#This Row],[Salesflo AppUser Code]],HIE!$A:$B,2,FALSE),0) -> 0 | T5: Ali Niazi | U5: Multan | V5: Adult Diapers | W5: Dadu | X5: =IFERROR(VLOOKUP( Table1[[#This Row],[Trim Distributor Code]],Sheet1!$A:$J,10,FALSE),0) -> Active
A6: Ali Nazi | B6: D0013OB10 | C6: Mubeen Amir | D6: Active | E6: D0013 | F6: Ab Trader | G6: COMTEX | H6: ADULT DIAPER | I6: COMTEXADULT DIAPER | J6: SKU00691 | K6: 2.5 | L6: Active | M6: =Table1[[#This Row],[Cases]]*Table1[[#This Row],[Pack Size]] -> 0 | N6: =Table1[[#This Row],[Cases]]*Table1[[#This Row],[Pack Size]] -> 250 | O6: =IFERROR(VLOOKUP(Table1[[#This Row],[SKU Code]],'SKU Size'!$G:$H,2,FALSE),0)*Table1[[#This Row],[Cases]] -> 18900.061 | P6: =TRIM(E6) -> D0013 | Q6: =IFERROR(VLOOKUP(Table1[[#This Row],[Trim Distributor Code]],Sheet1!$N:$O,2,FALSE),0) -> D0381 | R6: =IFERROR(VLOOKUP(Table1[[#This Row],[Salesflo AppUser Code]],HIE!$A:$B,2,FALSE),0) -> 0 | S6: =IFERROR(VLOOKUP(Table1[[#This Row],[Salesflo AppUser Code]],HIE!$A:$B,2,FALSE),0) -> 0 | T6: Ali Niazi | U6: Multan | V6: Adult Diapers | W6: Comtex | X6: =IFERROR(VLOOKUP( Table1[[#This Row],[Trim Distributor Code]],Sheet1!$A:$J,10,FALSE),0) -> Active
A7: Ali Nazi | B7: D0013OB10 | C7: Mubeen Amir | D7: Active | E7: D0013 | F7: Ab Trader | G7: DIDI | H7: SANITARY NAPKIN | I7: DIDISANITARY NAPKIN | J7: SKU00724 | K7: 10 | L7: Active | M7: =Table1[[#This Row],[Cases]]*Table1[[#This Row],[Pack Size]] -> 0 | N7: =Table1[[#This Row],[Cases]]*Table1[[#This Row],[Pack Size]] -> 4800 | O7: =IFERROR(VLOOKUP(Table1[[#This Row],[SKU Code]],'SKU Size'!$G:$H,2,FALSE),0)*Table1[[#This Row],[Cases]] -> 48135.308 | P7: =TRIM(E7) -> D0013 | Q7: =IFERROR(VLOOKUP(Table1[[#This Row],[Trim Distributor Code]],Sheet1!$N:$O,2,FALSE),0) -> D0381 | R7: =IFERROR(VLOOKUP(Table1[[#This Row],[Salesflo AppUser Code]],HIE!$A:$B,2,FALSE),0) -> 0 | S7: =IFERROR(VLOOKUP(Table1[[#This Row],[Salesflo AppUser Code]],HIE!$A:$B,2,FALSE),0) -> 0 | T7: Ali Niazi | U7: Multan | V7: Sanitary Napkin | W7: Didi | X7: =IFERROR(VLOOKUP( Table1[[#This Row],[Trim Distributor Code]],Sheet1!$A:$J,10,FALSE),0) -> Active
A8: Ali Nazi | B8: D0013OB10 | C8: Mubeen Amir | D8: Active | E8: D0013 | F8: Ab Trader | G8: DIDI | H8: WIPES | I8: DIDIWIPES | J8: SKU00352 | K8: 10 | L8: Active | M8: =Table1[[#This Row],[Cases]]*Table1[[#This Row],[Pack Size]] -> 0 | N8: =Table1[[#This Row],[Cases]]*Table1[[#This Row],[Pack Size]] -> 240 | O8: =IFERROR(VLOOKUP(Table1[[#This Row],[SKU Code]],'SKU Size'!$G:$H,2,FALSE),0)*Table1[[#This Row],[Cases]] -> 19303.368 | P8: =TRIM(E8) -> D0013 | Q8: =IFERROR(VLOOKUP(Table1[[#This Row],[Trim Distributor Code]],Sheet1!$N:$O,2,FALSE),0) -> D0381 | R8: =IFERROR(VLOOKUP(Table1[[#This Row],[Salesflo AppUser Code]],HIE!$A:$B,2,FALSE),0) -> 0 | S8: =IFERROR(VLOOKUP(Table1[[#This Row],[Salesflo AppUser Code]],HIE!$A:$B,2,FALSE),0) -> 0 | T8: Ali Niazi | U8: Multan | V8: Wipes | W8: Didi | X8: =IFERROR(VLOOKUP( Table1[[#This Row],[Trim Distributor Code]],Sheet1!$A:$J,10,FALSE),0) -> Active
A9: Ali Nazi | B9: D0013OB11 | C9: Muazam | D9: Active | E9: D0013 | F9: Ab Trader | G9: NANA SMARTY | H9: DIAPER | I9: NANA SMARTYDIAPER | J9: SKU00323 | K9: 140 | L9: Active | M9: =Table1[[#This Row],[Cases]]*Table1[[#This Row],[Pack Size]] -> 0 | N9: =Table1[[#This Row],[Cases]]*Table1[[#This Row],[Pack Size]] -> 56000 | O9: =IFERROR(VLOOKUP(Table1[[#This Row],[SKU Code]],'SKU Size'!$G:$H,2,FALSE),0)*Table1[[#This Row],[Cases]] -> 1267265.2 | P9: =TRIM(E9) -> D0013 | Q9: =IFERROR(VLOOKUP(Table1[[#This Row],[Trim Distributor Code]],Sheet1!$N:$O,2,FALSE),0) -> D0381 | R9: =IFERROR(VLOOKUP(Table1[[#This Row],[Salesflo AppUser Code]],HIE!$A:$B,2,FALSE),0) -> 0 | S9: =IFERROR(VLOOKUP(Table1[[#This Row],[Salesflo AppUser Code]],HIE!$A:$B,2,FALSE),0) -> 0 | T9: Ali Niazi | U9: Multan | V9: Baby Diapers | W9: NaNa | X9: =IFERROR(VLOOKUP( Table1[[#This Row],[Trim Distributor Code]],Sheet1!$A:$J,10,FALSE),0) -> Active
A10: Ali Nazi | B10: D0013OB11 | C10: Muazam | D10: Active | E10: D0013 | F10: Ab Trader | G10: NANA SMARTY | H10: PANTS | I10: NANA SMARTYPANTS | J10: SKU00344 | K10: 2.5 | L10: Active | M10: =Table1[[#This Row],[Cases]]*Table1[[#This Row],[Pack Size]] -> 0 | N10: =Table1[[#This Row],[Cases]]*Table1[[#This Row],[Pack Size]] -> 960 | O10: =IFERROR(VLOOKUP(Table1[[#This Row],[SKU Code]],'SKU Size'!$G:$H,2,FALSE),0)*Table1[[#This Row],[Cases]] -> 23298.474 | P10: =TRIM(E10) -> D0013 | Q10: =IFERROR(VLOOKUP(Table1[[#This Row],[Trim Distributor Code]],Sheet1!$N:$O,2,FALSE),0) -> D0381 | R10: =IFERROR(VLOOKUP(Table1[[#This Row],[Salesflo AppUser Code]],HIE!$A:$B,2,FALSE),0) -> 0 | S10: =IFERROR(VLOOKUP(Table1[[#This Row],[Salesflo AppUser Code]],HIE!$A:$B,2,FALSE),0) -> 0 | T10: Ali Niazi | U10: Multan | V10: Pants | W10: NaNa | X10: =IFERROR(VLOOKUP( Table1[[#This Row],[Trim Distributor Code]],Sheet1!$A:$J,10,FALSE),0) -> Active
A11: Ali Nazi | B11: D0013OB11 | C11: Muazam | D11: Active | E11: D0013 | F11: Ab Trader | G11: NANA SMARTY | H11: WIPES | I11: NANA SMARTYWIPES | J11: SKU00342 | K11: 5 | L11: Active | M11: =Table1[[#This Row],[Cases]]*Table1[[#This Row],[Pack Size]] -> 0 | N11: =Table1[[#This Row],[Cases]]*Table1[[#This Row],[Pack Size]] -> 120 | O11: =IFERROR(VLOOKUP(Table1[[#This Row],[SKU Code]],'SKU Size'!$G:$H,2,FALSE),0)*Table1[[#This Row],[Cases]] -> 17220.323 | P11: =TRIM(E11) -> D0013 | Q11: =IFERROR(VLOOKUP(Table1[[#This Row],[Trim Distributor Code]],Sheet1!$N:$O,2,FALSE),0) -> D0381 | R11: =IFERROR(VLOOKUP(Table1[[#This Row],[Salesflo AppUser Code]],HIE!$A:$B,2,FALSE),0) -> 0 | S11: =IFERROR(VLOOKUP(Table1[[#This Row],[Salesflo AppUser Code]],HIE!$A:$B,2,FALSE),0) -> 0 | T11: Ali Niazi | U11: Multan | V11: Wipes | W11: NaNa | X11: =IFERROR(VLOOKUP( Table1[[#This Row],[Trim Distributor Code]],Sheet1!$A:$J,10,FALSE),0) -> Active
A12: Ali Nazi | B12: D0013OB11 | C12: Muazam | D12: Active | E12: D0013 | F12: Ab Trader | G12: DADU | H12: ADULT DIAPER | I12: DADUADULT DIAPER | J12: SKU00340 | K12: 10 | L12: Active | M12: =Table1[[#This Row],[Cases]]*Table1[[#This Row],[Pack Size]] -> 0 | N12: =Table1[[#This Row],[Cases]]*Table1[[#This Row],[Pack Size]] -> 1000 | O12: =IFERROR(VLOOKUP(Table1[[#This Row],[SKU Code]],'SKU Size'!$G:$H,2,FALSE),0)*Table1[[#This Row],[Cases]] -> 101712.54 | P12: =TRIM(E12) -> D0013 | Q12: =IFERROR(VLOOKUP(Table1[[#This Row],[Trim Distributor Code]],Sheet1!$N:$O,2,FALSE),0) -> D0381 | R12: =IFERROR(VLOOKUP(Table1[[#This Row],[Salesflo AppUser Code]],HIE!$A:$B,2,FALSE),0) -> 0 | S12: =IFERROR(VLOOKUP(Table1[[#This Row],[Salesflo AppUser Code]],HIE!$A:$B,2,FALSE),0) -> 0 | T12: Ali Niazi | U12: Multan | V12: Adult Diapers | W12: Dadu | X12: =IFERROR(VLOOKUP( Table1[[#This Row],[Trim Distributor Code]],Sheet1!$A:$J,10,FALSE),0) -> Active
A13: Ali Nazi | B13: D0013OB11 | C13: Muazam | D13: Active | E13: D0013 | F13: Ab Trader | G13: COMTEX | H13: ADULT DIAPER | I13: COMTEXADULT DIAPER | J13: SKU00691 | K13: 2.5 | L13: Active | M13: =Table1[[#This Row],[Cases]]*Table1[[#This Row],[Pack Size]] -> 0 | N13: =Table1[[#This Row],[Cases]]*Table1[[#This Row],[Pack Size]] -> 250 | O13: =IFERROR(VLOOKUP(Table1[[#This Row],[SKU Code]],'SKU Size'!$G:$H,2,FALSE),0)*Table1[[#This Row],[Cases]] -> 18900.061 | P13: =TRIM(E13) -> D0013 | Q13: =IFERROR(VLOOKUP(Table1[[#This Row],[Trim Distributor Code]],Sheet1!$N:$O,2,FALSE),0) -> D0381 | R13: =IFERROR(VLOOKUP(Table1[[#This Row],[Salesflo AppUser Code]],HIE!$A:$B,2,FALSE),0) -> 0 | S13: =IFERROR(VLOOKUP(Table1[[#This Row],[Salesflo AppUser Code]],HIE!$A:$B,2,FALSE),0) -> 0 | T13: Ali Niazi | U13: Multan | V13: Adult Diapers | W13: Comtex | X13: =IFERROR(VLOOKUP( Table1[[#This Row],[Trim Distributor Code]],Sheet1!$A:$J,10,FALSE),0) -> Active
... A365: Raza (Ali Nazi) | B365: D0314OB3 | C365: Tanveer Shahzad Shahzad Outstations | D365: Active | E365: D0314 | F365: MJ Traders | G365: Didi | H365: WIPES | I365: DidiWIPES | J365: SKU00588 | K365: 20 | L365: Active | M365: =Table1[[#This Row],[Cases]]*Table1[[#This Row],[Pack Size]] -> 0 | N365: =Table1[[#This Row],[Cases]]*Table1[[#This Row],[Pack Size]] -> 480 | O365: =IFERROR(VLOOKUP(Table1[[#This Row],[SKU Code]],'SKU Size'!$G:$H,2,FALSE),0)*Table1[[#This Row],[Cases]] -> 164.11825 | P365: =TRIM(E365) -> D0314 | Q365: =IFERROR(VLOOKUP(Table1[[#This Row],[Trim Distributor Code]],Sheet1!$N:$O,2,FALSE),0) -> 3400842 | R365: =IFERROR(VLOOKUP(Table1[[#This Row],[Salesflo AppUser Code]],HIE!$A:$B,2,FALSE),0) -> Active | S365: =IFERROR(VLOOKUP(Table1[[#This Row],[Salesflo AppUser Code]],HIE!$A:$B,2,FALSE),0) -> Active | T365: Ali Niazi | U365: Multan | V365: Wipes | W365: Didi | X365: =IFERROR(VLOOKUP( Table1[[#This Row],[Trim Distributor Code]],Sheet1!$A:$J,10,FALSE),0) -> Active
A366: Raza (Ali Nazi) | B366: D0422OB1 | C366: Adeel Shahzad | D366: 0 | E366: D0422 | F366: Perfect Marketing | G366: BONA MAGIC | H366: DIAPER | I366: BONA MAGICDIAPER | J366: SKU00300 | K366: 260 | L366: Active | M366: =Table1[[#This Row],[Cases]]*Table1[[#This Row],[Pack Size]] -> 0 | N366: =Table1[[#This Row],[Cases]]*Table1[[#This Row],[Pack Size]] -> 91520 | O366: =IFERROR(VLOOKUP(Table1[[#This Row],[SKU Code]],'SKU Size'!$G:$H,2,FALSE),0)*Table1[[#This Row],[Cases]] -> 2278834.5 | P366: =TRIM(E366) -> D0422 | Q366: =IFERROR(VLOOKUP(Table1[[#This Row],[Trim Distributor Code]],Sheet1!$N:$O,2,FALSE),0) -> 3400996 | R366: =IFERROR(VLOOKUP(Table1[[#This Row],[Salesflo AppUser Code]],HIE!$A:$B,2,FALSE),0) -> Active | S366: =IFERROR(VLOOKUP(Table1[[#This Row],[Salesflo AppUser Code]],HIE!$A:$B,2,FALSE),0) -> Active | T366: Ali Niazi | U366: Multan | V366: Baby Diapers | W366: Bona Magic | X366: =IFERROR(VLOOKUP( Table1[[#This Row],[Trim Distributor Code]],Sheet1!$A:$J,10,FALSE),0) -> Active
A367: Raza (Ali Nazi) | B367: D0422OB1 | C367: Adeel Shahzad | D367: 0 | E367: D0422 | F367: Perfect Marketing | G367: TRULY | H367: ADULT DIAPER | I367: TRULYADULT DIAPER | J367: SKU00695 | K367: 3 | L367: Active | M367: =Table1[[#This Row],[Cases]]*Table1[[#This Row],[Pack Size]] -> 0 | N367: =Table1[[#This Row],[Cases]]*Table1[[#This Row],[Pack Size]] -> 300 | O367: =IFERROR(VLOOKUP(Table1[[#This Row],[SKU Code]],'SKU Size'!$G:$H,2,FALSE),0)*Table1[[#This Row],[Cases]] -> 22641.404 | P367: =TRIM(E367) -> D0422 | Q367: =IFERROR(VLOOKUP(Table1[[#This Row],[Trim Distributor Code]],Sheet1!$N:$O,2,FALSE),0) -> 3400996 | R367: =IFERROR(VLOOKUP(Table1[[#This Row],[Salesflo AppUser Code]],HIE!$A:$B,2,FALSE),0) -> Active | S367: =IFERROR(VLOOKUP(Table1[[#This Row],[Salesflo AppUser Code]],HIE!$A:$B,2,FALSE),0) -> Active | T367: Ali Niazi | U367: Multan | V367: Adult Diapers | W367: Truly | X367: =IFERROR(VLOOKUP( Table1[[#This Row],[Trim Distributor Code]],Sheet1!$A:$J,10,FALSE),0) -> Active
A368: Raza (Ali Nazi) | B368: D0422OB1 | C368: Adeel Shahzad | D368: 0 | E368: D0422 | F368: Perfect Marketing | G368: BONA MAGIC | H368: WIPES | I368: BONA MAGICWIPES | J368: SKU00292 | K368: 10 | L368: Active | M368: =Table1[[#This Row],[Cases]]*Table1[[#This Row],[Pack Size]] -> 0 | N368: =Table1[[#This Row],[Cases]]*Table1[[#This Row],[Pack Size]] -> 240 | O368: =IFERROR(VLOOKUP(Table1[[#This Row],[SKU Code]],'SKU Size'!$G:$H,2,FALSE),0)*Table1[[#This Row],[Cases]] -> 35914.733 | P368: =TRIM(E368) -> D0422 | Q368: =IFERROR(VLOOKUP(Table1[[#This Row],[Trim Distributor Code]],Sheet1!$N:$O,2,FALSE),0) -> 3400996 | R368: =IFERROR(VLOOKUP(Table1[[#This Row],[Salesflo AppUser Code]],HIE!$A:$B,2,FALSE),0) -> Active | S368: =IFERROR(VLOOKUP(Table1[[#This Row],[Salesflo AppUser Code]],HIE!$A:$B,2,FALSE),0) -> Active | T368: Ali Niazi | U368: Multan | V368: Wipes | W368: Bona Magic | X368: =IFERROR(VLOOKUP( Table1[[#This Row],[Trim Distributor Code]],Sheet1!$A:$J,10,FALSE),0) -> Active
A369: Raza (Ali Nazi) | B369: D0422OB1 | C369: Adeel Shahzad | D369: 0 | E369: D0422 | F369: Perfect Marketing | G369: SAFA CARE | H369: WIPES | I369: SAFA CAREWIPES | J369: SKU00698 | K369: 10 | L369: Active | M369: =Table1[[#This Row],[Cases]]*Table1[[#This Row],[Pack Size]] -> 0 | N369: =Table1[[#This Row],[Cases]]*Table1[[#This Row],[Pack Size]] -> 480 | O369: =IFERROR(VLOOKUP(Table1[[#This Row],[SKU Code]],'SKU Size'!$G:$H,2,FALSE),0)*Table1[[#This Row],[Cases]] -> 10039.149 | P369: =TRIM(E369) -> D0422 | Q369: =IFERROR(VLOOKUP(Table1[[#This Row],[Trim Distributor Code]],Sheet1!$N:$O,2,FALSE),0) -> 3400996 | R369: =IFERROR(VLOOKUP(Table1[[#This Row],[Salesflo AppUser Code]],HIE!$A:$B,2,FALSE),0) -> Active | S369: =IFERROR(VLOOKUP(Table1[[#This Row],[Salesflo AppUser Code]],HIE!$A:$B,2,FALSE),0) -> Active | T369: Ali Niazi | U369: Multan | V369: Wipes | W369: Safa Care | X369: =IFERROR(VLOOKUP( Table1[[#This Row],[Trim Distributor Code]],Sheet1!$A:$J,10,FALSE),0) -> Active
A370: Raza (Ali Nazi) | B370: D0422OB1 | C370: Adeel Shahzad | D370: 0 | E370: D0422 | F370: Perfect Marketing | G370: TEGRA | H370: PERSONAL CARE | I370: TEGRAPERSONAL CARE | J370: SKU00530 | K370: 2 | L370: Active | M370: =Table1[[#This Row],[Cases]]*Table1[[#This Row],[Pack Size]] -> 0 | N370: =Table1[[#This Row],[Cases]]*Table1[[#This Row],[Pack Size]] -> 576 | O370: =IFERROR(VLOOKUP(Table1[[#This Row],[SKU Code]],'SKU Size'!$G:$H,2,FALSE),0)*Table1[[#This Row],[Cases]] -> 9706.8585 | P370: =TRIM(E370) -> D0422 | Q370: =IFERROR(VLOOKUP(Table1[[#This Row],[Trim Distributor Code]],Sheet1!$N:$O,2,FALSE),0) -> 3400996 | R370: =IFERROR(VLOOKUP(Table1[[#This Row],[Salesflo AppUser Code]],HIE!$A:$B,2,FALSE),0) -> Active | S370: =IFERROR(VLOOKUP(Table1[[#This Row],[Salesflo AppUser Code]],HIE!$A:$B,2,FALSE),0) -> Active | T370: Ali Niazi | U370: Multan | V370: Personal Care | W370: Tegra RZ | X370: =IFERROR(VLOOKUP( Table1[[#This Row],[Trim Distributor Code]],Sheet1!$A:$J,10,FALSE),0) -> Active
A371: Raza (Ali Nazi) | B371: D0422OB1 | C371: Adeel Shahzad | D371: 0 | E371: D0422 | F371: Perfect Marketing | G371: TEGRA | H371: ORAL CARE | I371: TEGRAORAL CARE | J371: SKU00535 | K371: 2 | L371: Active | M371: =Table1[[#This Row],[Cases]]*Table1[[#This Row],[Pack Size]] -> 0 | N371: =Table1[[#This Row],[Cases]]*Table1[[#This Row],[Pack Size]] -> 288 | O371: =IFERROR(VLOOKUP(Table1[[#This Row],[SKU Code]],'SKU Size'!$G:$H,2,FALSE),0)*Table1[[#This Row],[Cases]] -> 11050.978 | P371: =TRIM(E371) -> D0422 | Q371: =IFERROR(VLOOKUP(Table1[[#This Row],[Trim Distributor Code]],Sheet1!$N:$O,2,FALSE),0) -> 3400996 | R371: =IFERROR(VLOOKUP(Table1[[#This Row],[Salesflo AppUser Code]],HIE!$A:$B,2,FALSE),0) -> Active | S371: =IFERROR(VLOOKUP(Table1[[#This Row],[Salesflo AppUser Code]],HIE!$A:$B,2,FALSE),0) -> Active | T371: Ali Niazi | U371: Multan | V371: Oral Care | W371: Tegra TB | X371: =IFERROR(VLOOKUP( Table1[[#This Row],[Trim Distributor Code]],Sheet1!$A:$J,10,FALSE),0) -> Active
A372: Raza (Ali Nazi) | B372: D0422OB2 | C372: Jahanzaib Javaid | D372: 0 | E372: D0422 | F372: Perfect Marketing | G372: BONA MAGIC | H372: DIAPER | I372: BONA MAGICDIAPER | J372: SKU00300 | K372: 375 | L372: Active | M372: =Table1[[#This Row],[Cases]]*Table1[[#This Row],[Pack Size]] -> 0 | N372: =Table1[[#This Row],[Cases]]*Table1[[#This Row],[Pack Size]] -> 132000 | O372: =IFERROR(VLOOKUP(Table1[[#This Row],[SKU Code]],'SKU Size'!$G:$H,2,FALSE),0)*Table1[[#This Row],[Cases]] -> 3286780.6 | P372: =TRIM(E372) -> D0422 | Q372: =IFERROR(VLOOKUP(Table1[[#This Row],[Trim Distributor Code]],Sheet1!$N:$O,2,FALSE),0) -> 3400996 | R372: =IFERROR(VLOOKUP(Table1[[#This Row],[Salesflo AppUser Code]],HIE!$A:$B,2,FALSE),0) -> Active | S372: =IFERROR(VLOOKUP(Table1[[#This Row],[Salesflo AppUser Code]],HIE!$A:$B,2,FALSE),0) -> Active | T372: Ali Niazi | U372: Multan | V372: Baby Diapers | W372: Bona Magic | X372: =IFERROR(VLOOKUP( Table1[[#This Row],[Trim Distributor Code]],Sheet1!$A:$J,10,FALSE),0) -> Active
A373: Raza (Ali Nazi) | B373: D0422OB2 | C373: Jahanzaib Javaid | D373: 0 | E373: D0422 | F373: Perfect Marketing | G373: TRULY | H373: ADULT DIAPER | I373: TRULYADULT DIAPER | J373: SKU00695 | K373: 5 | L373: Active | M373: =Table1[[#This Row],[Cases]]*Table1[[#This Row],[Pack Size]] -> 0 | N373: =Table1[[#This Row],[Cases]]*Table1[[#This Row],[Pack Size]] -> 500 | O373: =IFERROR(VLOOKUP(Table1[[#This Row],[SKU Code]],'SKU Size'!$G:$H,2,FALSE),0)*Table1[[#This Row],[Cases]] -> 37735.674 | P373: =TRIM(E373) -> D0422 | Q373: =IFERROR(VLOOKUP(Table1[[#This Row],[Trim Distributor Code]],Sheet1!$N:$O,2,FALSE),0) -> 3400996 | R373: =IFERROR(VLOOKUP(Table1[[#This Row],[Salesflo AppUser Code]],HIE!$A:$B,2,FALSE),0) -> Active | S373: =IFERROR(VLOOKUP(Table1[[#This Row],[Salesflo AppUser Code]],HIE!$A:$B,2,FALSE),0) -> Active | T373: Ali Niazi | U373: Multan | V373: Adult Diapers | W373: Truly | X373: =IFERROR(VLOOKUP( Table1[[#This Row],[Trim Distributor Code]],Sheet1!$A:$J,10,FALSE),0) -> Active
A374: Raza (Ali Nazi) | B374: D0422OB2 | C374: Jahanzaib Javaid | D374: 0 | E374: D0422 | F374: Perfect Marketing | G374: BONA MAGIC | H374: WIPES | I374: BONA MAGICWIPES | J374: SKU00292 | K374: 20 | L374: Active | M374: =Table1[[#This Row],[Cases]]*Table1[[#This Row],[Pack Size]] -> 0 | N374: =Table1[[#This Row],[Cases]]*Table1[[#This Row],[Pack Size]] -> 480 | O374: =IFERROR(VLOOKUP(Table1[[#This Row],[SKU Code]],'SKU Size'!$G:$H,2,FALSE),0)*Table1[[#This Row],[Cases]] -> 71829.465 | P374: =TRIM(E374) -> D0422 | Q374: =IFERROR(VLOOKUP(Table1[[#This Row],[Trim Distributor Code]],Sheet1!$N:$O,2,FALSE),0) -> 3400996 | R374: =IFERROR(VLOOKUP(Table1[[#This Row],[Salesflo AppUser Code]],HIE!$A:$B,2,FALSE),0) -> Active | S374: =IFERROR(VLOOKUP(Table1[[#This Row],[Salesflo AppUser Code]],HIE!$A:$B,2,FALSE),0) -> Active | T374: Ali Niazi | U374: Multan | V374: Wipes | W374: Bona Magic | X374: =IFERROR(VLOOKUP( Table1[[#This Row],[Trim Distributor Code]],Sheet1!$A:$J,10,FALSE),0) -> Active
A375: Raza (Ali Nazi) | B375: D0422OB3 | C375: Amir Aslam | D375: 0 | E375: D0422 | F375: Perfect Marketing | G375: BONA MAGIC | H375: DIAPER | I375: BONA MAGICDIAPER | J375: SKU00300 | K375: 250 | L375: Active | M375: =Table1[[#This Row],[Cases]]*Table1[[#This Row],[Pack Size]] -> 0 | N375: =Table1[[#This Row],[Cases]]*Table1[[#This Row],[Pack Size]] -> 88000 | O375: =IFERROR(VLOOKUP(Table1[[#This Row],[SKU Code]],'SKU Size'!$G:$H,2,FALSE),0)*Table1[[#This Row],[Cases]] -> 2191187.1 | P375: =TRIM(E375) -> D0422 | Q375: =IFERROR(VLOOKUP(Table1[[#This Row],[Trim Distributor Code]],Sheet1!$N:$O,2,FALSE),0) -> 3400996 | R375: =IFERROR(VLOOKUP(Table1[[#This Row],[Salesflo AppUser Code]],HIE!$A:$B,2,FALSE),0) -> Active | S375: =IFERROR(VLOOKUP(Table1[[#This Row],[Salesflo AppUser Code]],HIE!$A:$B,2,FALSE),0) -> Active | T375: Ali Niazi | U375: Multan | V375: Baby Diapers | W375: Bona Magic | X375: =IFERROR(VLOOKUP( Table1[[#This Row],[Trim Distributor Code]],Sheet1!$A:$J,10,FALSE),0) -> Active
A376: Raza (Ali Nazi) | B376: D0422OB3 | C376: Amir Aslam | D376: 0 | E376: D0422 | F376: Perfect Marketing | G376: TRULY | H376: ADULT DIAPER | I376: TRULYADULT DIAPER | J376: SKU00695 | K376: 3 | L376: Active | M376: =Table1[[#This Row],[Cases]]*Table1[[#This Row],[Pack Size]] -> 0 | N376: =Table1[[#This Row],[Cases]]*Table1[[#This Row],[Pack Size]] -> 300 | O376: =IFERROR(VLOOKUP(Table1[[#This Row],[SKU Code]],'SKU Size'!$G:$H,2,FALSE),0)*Table1[[#This Row],[Cases]] -> 22641.404 | P376: =TRIM(E376) -> D0422 | Q376: =IFERROR(VLOOKUP(Table1[[#This Row],[Trim Distributor Code]],Sheet1!$N:$O,2,FALSE),0) -> 3400996 | R376: =IFERROR(VLOOKUP(Table1[[#This Row],[Salesflo AppUser Code]],HIE!$A:$B,2,FALSE),0) -> Active | S376: =IFERROR(VLOOKUP(Table1[[#This Row],[Salesflo AppUser Code]],HIE!$A:$B,2,FALSE),0) -> Active | T376: Ali Niazi | U376: Multan | V376: Adult Diapers | W376: Truly | X376: =IFERROR(VLOOKUP( Table1[[#This Row],[Trim Distributor Code]],Sheet1!$A:$J,10,FALSE),0) -> Active
A377: Raza (Ali Nazi) | B377: D0422OB3 | C377: Amir Aslam | D377: 0 | E377: D0422 | F377: Perfect Marketing | G377: BONA MAGIC | H377: WIPES | I377: BONA MAGICWIPES | J377: SKU00292 | K377: 5 | L377: Active | M377: =Table1[[#This Row],[Cases]]*Table1[[#This Row],[Pack Size]] -> 0 | N377: =Table1[[#This Row],[Cases]]*Table1[[#This Row],[Pack Size]] -> 120 | O377: =IFERROR(VLOOKUP(Table1[[#This Row],[SKU Code]],'SKU Size'!$G:$H,2,FALSE),0)*Table1[[#This Row],[Cases]] -> 17957.366 | P377: =TRIM(E377) -> D0422 | Q377: =IFERROR(VLOOKUP(Table1[[#This Row],[Trim Distributor Code]],Sheet1!$N:$O,2,FALSE),0) -> 3400996 | R377: =IFERROR(VLOOKUP(Table1[[#This Row],[Salesflo AppUser Code]],HIE!$A:$B,2,FALSE),0) -> Active | S377: =IFERROR(VLOOKUP(Table1[[#This Row],[Salesflo AppUser Code]],HIE!$A:$B,2,FALSE),0) -> Active | T377: Ali Niazi | U377: Multan | V377: Wipes | W377: Bona Magic | X377: =IFERROR(VLOOKUP( Table1[[#This Row],[Trim Distributor Code]],Sheet1!$A:$J,10,FALSE),0) -> Active
... A499: Raza (Ali Nazi) | B499: D0426OB2 | C499: Husnain Murtaza | D499: 0 | E499: D0426 | F499: Pakistan Traders | G499: SAFA CARE | H499: WIPES | I499: SAFA CAREWIPES | J499: SKU00698 | K499: 10 | L499: Active | M499: =Table1[[#This Row],[Cases]]*Table1[[#This Row],[Pack Size]] -> 0 | N499: =Table1[[#This Row],[Cases]]*Table1[[#This Row],[Pack Size]] -> 480 | O499: =IFERROR(VLOOKUP(Table1[[#This Row],[SKU Code]],'SKU Size'!$G:$H,2,FALSE),0)*Table1[[#This Row],[Cases]] -> 10039.149 | P499: =TRIM(E499) -> D0426 | Q499: =IFERROR(VLOOKUP(Table1[[#This Row],[Trim Distributor Code]],Sheet1!$N:$O,2,FALSE),0) -> 3401003 | R499: =IFERROR(VLOOKUP(Table1[[#This Row],[Salesflo AppUser Code]],HIE!$A:$B,2,FALSE),0) -> 0 | S499: =IFERROR(VLOOKUP(Table1[[#This Row],[Salesflo AppUser Code]],HIE!$A:$B,2,FALSE),0) -> 0 | T499: Ali Niazi | U499: Multan | V499: Wipes | W499: Safa Care | X499: =IFERROR(VLOOKUP( Table1[[#This Row],[Trim Distributor Code]],Sheet1!$A:$J,10,FALSE),0) -> Active
A500: Umer hayat | B500: D0067OB5 | C500: Umer hayat | D500: Active | E500: D0067 | F500: Wahid Traders | G500: BONA MAGIC | H500: DIAPER | I500: BONA MAGICDIAPER | J500: SKU00300 | K500: 80 | L500: Active | M500: =Table1[[#This Row],[Cases]]*Table1[[#This Row],[Pack Size]] -> 0 | N500: =Table1[[#This Row],[Cases]]*Table1[[#This Row],[Pack Size]] -> 28160 | O500: =IFERROR(VLOOKUP(Table1[[#This Row],[SKU Code]],'SKU Size'!$G:$H,2,FALSE),0)*Table1[[#This Row],[Cases]] -> 701179.86 | P500: =TRIM(E500) -> D0067 | Q500: =IFERROR(VLOOKUP(Table1[[#This Row],[Trim Distributor Code]],Sheet1!$N:$O,2,FALSE),0) -> 3400021 | R500: =IFERROR(VLOOKUP(Table1[[#This Row],[Salesflo AppUser Code]],HIE!$A:$B,2,FALSE),0) -> Active | S500: =IFERROR(VLOOKUP(Table1[[#This Row],[Salesflo AppUser Code]],HIE!$A:$B,2,FALSE),0) -> Active | T500: Amir Tayyab | U500: South Plus & Super | V500: Baby Diapers | W500: Bona Magic | X500: =IFERROR(VLOOKUP( Table1[[#This Row],[Trim Distributor Code]],Sheet1!$A:$J,10,FALSE),0) -> Active
A501: Umer hayat | B501: D0067OB5 | C501: Umer hayat | D501: Active | E501: D0067 | F501: Wahid Traders | G501: BONA MAGIC | H501: PANTS | I501: BONA MAGICPANTS | J501: SKU00296 | K501: 50 | L501: Active | M501: =Table1[[#This Row],[Cases]]*Table1[[#This Row],[Pack Size]] -> 0 | N501: =Table1[[#This Row],[Cases]]*Table1[[#This Row],[Pack Size]] -> 18000 | O501: =IFERROR(VLOOKUP(Table1[[#This Row],[SKU Code]],'SKU Size'!$G:$H,2,FALSE),0)*Table1[[#This Row],[Cases]] -> 455689.21 | P501: =TRIM(E501) -> D0067 | Q501: =IFERROR(VLOOKUP(Table1[[#This Row],[Trim Distributor Code]],Sheet1!$N:$O,2,FALSE),0) -> 3400021 | R501: =IFERROR(VLOOKUP(Table1[[#This Row],[Salesflo AppUser Code]],HIE!$A:$B,2,FALSE),0) -> Active | S501: =IFERROR(VLOOKUP(Table1[[#This Row],[Salesflo AppUser Code]],HIE!$A:$B,2,FALSE),0) -> Active | T501: Amir Tayyab | U501: South Plus & Super | V501: Pants | W501: Bona Magic | X501: =IFERROR(VLOOKUP( Table1[[#This Row],[Trim Distributor Code]],Sheet1!$A:$J,10,FALSE),0) -> Active
A502: Umer hayat | B502: D0067OB5 | C502: Umer hayat | D502: Active | E502: D0067 | F502: Wahid Traders | G502: MIMI PAPA | H502: ADULT DIAPER | I502: MIMI PAPAADULT DIAPER | J502: SKU00269 | K502: 5 | L502: Active | M502: =Table1[[#This Row],[Cases]]*Table1[[#This Row],[Pack Size]] -> 0 | N502: =Table1[[#This Row],[Cases]]*Table1[[#This Row],[Pack Size]] -> 500 | O502: =IFERROR(VLOOKUP(Table1[[#This Row],[SKU Code]],'SKU Size'!$G:$H,2,FALSE),0)*Table1[[#This Row],[Cases]] -> 52843.37 | P502: =TRIM(E502) -> D0067 | Q502: =IFERROR(VLOOKUP(Table1[[#This Row],[Trim Distributor Code]],Sheet1!$N:$O,2,FALSE),0) -> 3400021 | R502: =IFERROR(VLOOKUP(Table1[[#This Row],[Salesflo AppUser Code]],HIE!$A:$B,2,FALSE),0) -> Active | S502: =IFERROR(VLOOKUP(Table1[[#This Row],[Salesflo AppUser Code]],HIE!$A:$B,2,FALSE),0) -> Active | T502: Amir Tayyab | U502: South Plus & Super | V502: Adult Diapers | W502: Mimi Papa | X502: =IFERROR(VLOOKUP( Table1[[#This Row],[Trim Distributor Code]],Sheet1!$A:$J,10,FALSE),0) -> Active
